2025-04-08T20:42:28-04:00 Your publish request with ID ecf5331f-294b-47b6-9edb-e88463dbe6ee is now being processed.
2025-04-08T20:42:28-04:00 Quarto version was not provided. Using 1.6.42
2025-04-08T20:42:28-04:00 Loading your source code...
2025-04-08T20:42:28-04:00 Initialized empty Git repository in /cloud/project/.git/
2025-04-08T20:42:29-04:00 From https://github.com/habadiotakis1/shiny_manuscript
2025-04-08T20:42:29-04:00  * branch            2af3d54e1ac763e3808597f765f9beabf3f3e7d2 -> FETCH_HEAD
2025-04-08T20:42:29-04:00 HEAD is now at 2af3d54 a
2025-04-08T20:42:32-04:00 Connect Cloud is providing the following 66 Python packages:
2025-04-08T20:42:32-04:00 anyio==4.9.0, anywidget==0.9.18, appdirs==1.4.4, asgiref==3.8.1, asttokens==3.0.0
2025-04-08T20:42:32-04:00 click==8.1.8, comm==0.2.2, decorator==5.2.1, executing==2.2.0, faicons==0.2.2
2025-04-08T20:42:32-04:00 h11==0.14.0, htmltools==0.6.0, httptools==0.6.4, idna==3.10, ipython==9.1.0
2025-04-08T20:42:32-04:00 ipython-pygments-lexers==1.1.1, ipywidgets==8.1.5, jedi==0.19.2, jupyter-core==5.7.2, jupyterlab-widgets==3.0.13
2025-04-08T20:42:32-04:00 linkify-it-py==2.0.3, markdown-it-py==3.0.0, matplotlib-inline==0.1.7, mdit-py-plugins==0.4.2, mdurl==0.1.2
2025-04-08T20:42:32-04:00 narwhals==1.34.0, numpy==2.2.4, orjson==3.10.16, packaging==24.2, pandas==2.2.3
2025-04-08T20:42:32-04:00 parso==0.8.4, patsy==1.0.1, pexpect==4.9.0, pillow==11.1.0, platformdirs==4.3.7
2025-04-08T20:42:32-04:00 plotly==6.0.1, prompt-toolkit==3.0.50, psygnal==0.12.0, ptyprocess==0.7.0, pure-eval==0.2.3
2025-04-08T20:42:32-04:00 pygments==2.19.1, python-dateutil==2.9.0.post0, python-dotenv==1.1.0, python-multipart==0.0.20, pytz==2025.2
2025-04-08T20:42:32-04:00 pyyaml==6.0.2, questionary==2.1.0, scipy==1.15.2, setuptools==78.1.0, shinywidgets==0.5.2
2025-04-08T20:42:32-04:00 six==1.17.0, sniffio==1.3.1, stack-data==0.6.3, starlette==0.46.1, statsmodels==0.14.4
2025-04-08T20:42:32-04:00 traitlets==5.14.3, typing-extensions==4.13.1, tzdata==2025.2, uc-micro-py==1.0.3, uvicorn==0.34.0
2025-04-08T20:42:32-04:00 uvloop==0.21.0, watchfiles==1.0.5, wcwidth==0.2.13, websockets==15.0.1, widgetsnbextension==4.0.13
2025-04-08T20:42:32-04:00 wsproto==1.2.0
2025-04-08T20:42:32-04:00 5 additional packages will be installed from the Internet.
2025-04-08T20:42:33-04:00 Resolved 71 packages in 928ms
2025-04-08T20:42:34-04:00 Prepared 5 packages in 586ms
2025-04-08T20:42:34-04:00 Installed 5 packages in 30ms
2025-04-08T20:42:34-04:00  + docx==0.2.4
2025-04-08T20:42:34-04:00  + lxml==5.3.2
2025-04-08T20:42:34-04:00  + python-docx==1.1.2
2025-04-08T20:42:34-04:00  + ridgeplot==0.3.2
2025-04-08T20:42:34-04:00  + shiny==1.4.0
2025-04-08T20:42:34-04:00 Quarto version was not provided. Using 1.6.42
2025-04-08T20:42:34-04:00 Using Quarto version: 1.6.42
2025-04-08T20:42:34-04:00 Running on host: deployment-019617ff-602365d7f328be0ef375e49bd806e588-deploqvhvm
2025-04-08T20:42:34-04:00 Process ID: 220
2025-04-08T20:42:34-04:00 Running as user: uid=10002(connect) gid=10002(connect) groups=10002(connect)
2025-04-08T20:42:34-04:00 Connect version: 2025.03.0
2025-04-08T20:42:34-04:00 LANG: C.UTF-8
2025-04-08T20:42:34-04:00 Working directory: /cloud/project
2025-04-08T20:42:34-04:00 Bootstrapping environment using Python 3.12.7 (main, Feb 25 2025, 22:33:41) [GCC 11.4.0] at /cloud/lib/venv/bin/python3
2025-04-08T20:42:34-04:00 Running content using the current Python environment
2025-04-08T20:42:34-04:00   from pkg_resources import parse_version
2025-04-08T20:42:34-04:00 Running content using Python "3.12.7 (main, Feb 25 2025, 22:33:41) [GCC 11.4.0]" at "/cloud/lib/venv/bin/python3"
2025-04-08T20:42:34-04:00 Loading code from "app"
2025-04-08T20:42:36-04:00 Unexpected error while running Python API: input_text() got an unexpected keyword argument 'disabled'
2025-04-08T20:42:36-04:00 Traceback (most recent call last):
2025-04-08T20:42:36-04:00   File "/opt/connect/connect-cloud-2025.03.0/python/connect_fastapi_runtime.py", line 643, in <module>
2025-04-08T20:42:36-04:00     main(sys.argv)
2025-04-08T20:42:36-04:00   File "/opt/connect/connect-cloud-2025.03.0/python/connect_fastapi_runtime.py", line 605, in main
2025-04-08T20:42:36-04:00     app = setup_asgi_application(
2025-04-08T20:42:36-04:00           ^^^^^^^^^^^^^^^^^^^^^^^
2025-04-08T20:42:36-04:00   File "/opt/connect/connect-cloud-2025.03.0/python/connect_fastapi_runtime.py", line 511, in setup_asgi_application
2025-04-08T20:42:36-04:00     user_app = import_app(entrypoint, app_mode)
2025-04-08T20:42:36-04:00                ^^^^^^^^^^^^^^^^^^^^^^^^^^^^^^^^
2025-04-08T20:42:36-04:00   File "/opt/connect/connect-cloud-2025.03.0/python/connect_common_runtime.py", line 124, in import_app
2025-04-08T20:42:36-04:00     module = import_module(module_name)
2025-04-08T20:42:36-04:00              ^^^^^^^^^^^^^^^^^^^^^^^^^^
2025-04-08T20:42:36-04:00   File "/opt/python/3.12.7/lib/python3.12/importlib/__init__.py", line 90, in import_module
2025-04-08T20:42:36-04:00     return _bootstrap._gcd_import(name[level:], package, level)
2025-04-08T20:42:36-04:00            ^^^^^^^^^^^^^^^^^^^^^^^^^^^^^^^^^^^^^^^^^^^^^^^^^^^^
2025-04-08T20:42:36-04:00   File "<frozen importlib._bootstrap>", line 1387, in _gcd_import
2025-04-08T20:42:36-04:00   File "<frozen importlib._bootstrap>", line 1360, in _find_and_load
2025-04-08T20:42:36-04:00   File "<frozen importlib._bootstrap>", line 1331, in _find_and_load_unlocked
2025-04-08T20:42:36-04:00   File "<frozen importlib._bootstrap>", line 935, in _load_unlocked
2025-04-08T20:42:36-04:00   File "<frozen importlib._bootstrap_external>", line 995, in exec_module
2025-04-08T20:42:36-04:00   File "<frozen importlib._bootstrap>", line 488, in _call_with_frames_removed
2025-04-08T20:42:36-04:00   File "/cloud/project/app.py", line 353, in <module>
2025-04-08T20:42:36-04:00     ui.input_text("subheading_1", "Subheading 1", placeholder="Enter subheading 1 name", disabled=True),
2025-04-08T20:42:36-04:00     ^^^^^^^^^^^^^^^^^^^^^^^^^^^^^^^^^^^^^^^^^^^^^^^^^^^^^^^^^^^^^^^^^^^^^^^^^^^^^^^^^^^^^^^^^^^^^^^^^^^
2025-04-08T20:42:36-04:00 TypeError: input_text() got an unexpected keyword argument 'disabled'
2025-04-08T20:42:36-04:00 Failed to publish content: Your application failed to start. error_id=4b8018d4-81db-4c45-9997-361f3012a3f1